<?xml version="1.0"?>
<robot name="four_wheel_car">
<link name="base_link">
   		<visual>
     			<geometry>
       				<box size="1.0 0.6 0.4"/>
     			</geometry>
			<material name="white">
				<color rgba="1 1 1 .5"/>
			</material>
   		</visual>		
 </link>

<link name="front_left_rotate">
   		<visual>
     			<geometry>
       				<cylinder length="0.16" radius="0.1"/>
     			</geometry>
			<material name="blue">
				<color rgba="0 0 0.8 1"/>
			</material>
   		</visual>
		
 </link>

<joint name="base_to_front_left_rotate" type="continuous">
                <origin rpy="0 0 0" xyz="0.4 0.2 -0.28"/>
   		<parent link="base_link"/>
   		<child link="front_left_rotate"/>
   		<axis xyz="0 0 1"/>  
 </joint>

<link name="front_right_rotate">
   		<visual>
     			<geometry>
       				<cylinder length="0.16" radius="0.1"/>
     			</geometry>
			<material name="blue">
				<color rgba="0 0 0.8 1"/>
			</material>
   		</visual>
		
 </link>

<joint name="base_to_front_right_rotate" type="continuous">
                <origin rpy="0 0 0" xyz="0.4 -0.2 -0.28"/>
   		<parent link="base_link"/>
   		<child link="front_right_rotate"/>
   		<axis xyz="0 0 1"/>  
 </joint>

<link name="back_left_rotate">
   		<visual>
     			<geometry>
       				<cylinder length="0.16" radius="0.1"/>
     			</geometry>
			<material name="blue">
				<color rgba="0 0 0.8 1"/>
			</material>
   		</visual>
		
 </link>

<joint name="base_to_back_left_rotate" type="continuous">
                <origin rpy="0 0 0" xyz="-0.4 0.2 -0.28"/>
   		<parent link="base_link"/>
   		<child link="back_left_rotate"/>
   		<axis xyz="0 0 1"/>  
 </joint>

<link name="back_right_rotate">
   		<visual>
     			<geometry>
       				<cylinder length="0.16" radius="0.1"/>
     			</geometry>
			<material name="blue">
				<color rgba="0 0 0.8 1"/>
			</material>
   		</visual>
		
 </link>

<joint name="base_to_back_right_rotate" type="continuous">
                <origin rpy="0 0 0" xyz="-0.4 -0.2 -0.28"/>
   		<parent link="base_link"/>
   		<child link="back_right_rotate"/>
   		<axis xyz="0 0 1"/>  
 </joint>

<link name="front_left_wheel_suporting">
   		<visual>
     			<geometry>
       				<box size="0.08 .04 .12"/>
     			</geometry>			
			<material name="blue">
				<color rgba="0 0 0.8 1"/>
			</material>
   		</visual>
		
 </link>

<joint name="front_left_rotate_to_wheel_suporting" type="fixed">
                <origin rpy="0 0 0" xyz="0 0 -0.14"/>
   		<parent link="front_left_rotate"/>
   		<child link="front_left_wheel_suporting"/>
 </joint>

<link name="front_right_wheel_suporting">
   		<visual>
     			<geometry>
       				<box size="0.08 .04 .12"/>
     			</geometry>			
			<material name="blue">
				<color rgba="0 0 0.8 1"/>
			</material>
   		</visual>
		
 </link>

<joint name="front_right_rotate_to_wheel_suporting" type="fixed">
                <origin rpy="0 0 0" xyz="0 0 -0.14"/>
   		<parent link="front_right_rotate"/>
   		<child link="front_right_wheel_suporting"/>
 </joint>

<link name="back_left_wheel_suporting">
   		<visual>
     			<geometry>
       				<box size="0.08 .04 .12"/>
     			</geometry>			
			<material name="blue">
				<color rgba="0 0 0.8 1"/>
			</material>
   		</visual>
		
 </link>

<joint name="back_left_rotate_to_wheel_suporting" type="fixed">
                <origin rpy="0 0 0" xyz="0 0 -0.14"/>
   		<parent link="back_left_rotate"/>
   		<child link="back_left_wheel_suporting"/>
 </joint>

<link name="back_right_wheel_suporting">
   		<visual>
     			<geometry>
       				<box size="0.08 .04 .12"/>
     			</geometry>			
			<material name="blue">
				<color rgba="0 0 0.8 1"/>
			</material>
   		</visual>
		
 </link>

<joint name="back_right_rotate_to_wheel_suporting" type="fixed">
                <origin rpy="0 0 0" xyz="0 0 -0.14"/>
   		<parent link="back_right_rotate"/>
   		<child link="back_right_wheel_suporting"/>
 </joint>

<link name="front_left_wheel">
   		<visual>
     			<geometry>
       				<cylinder length="0.02" radius="0.06"/>
     			</geometry>
   			<material name="black">
				<color rgba="0 0 0 1"/>
			</material>
		</visual>

 </link>

<joint name="front_left_rotate_to_wheel" type="continuous">
                <origin rpy="1.57075 0 0" xyz="0 0 -0.18"/>
   		<parent link="front_left_rotate"/>
   		<child link="front_left_wheel"/>
   		<axis xyz="0 0 1"/>  
 </joint>

<link name="front_right_wheel">
   		<visual>
     			<geometry>
       				<cylinder length="0.02" radius="0.06"/>
     			</geometry>
   			<material name="black">
				<color rgba="0 0 0 1"/>
			</material>
		</visual>

 </link>

<joint name="front_right_rotate_to_wheel" type="continuous">
                <origin rpy="1.57075 0 0" xyz="0 0 -0.18"/>
   		<parent link="front_right_rotate"/>
   		<child link="front_right_wheel"/>
   		<axis xyz="0 0 1"/>  
 </joint>

<link name="back_left_wheel">
   		<visual>
     			<geometry>
       				<cylinder length="0.02" radius="0.06"/>
     			</geometry>
   			<material name="black">
				<color rgba="0 0 0 1"/>
			</material>
		</visual>

 </link>

<joint name="back_left_rotate_to_wheel" type="continuous">
                <origin rpy="1.57075 0 0" xyz="0 0 -0.18"/>
   		<parent link="back_left_rotate"/>
   		<child link="back_left_wheel"/>
   		<axis xyz="0 0 1"/>  
 </joint>

<link name="back_right_wheel">
   		<visual>
     			<geometry>
       				<cylinder length="0.02" radius="0.06"/>
     			</geometry>
   			<material name="black">
				<color rgba="0 0 0 1"/>
			</material>
		</visual>

 </link>

<joint name="back_right_rotate_to_wheel" type="continuous">
                <origin rpy="1.57075 0 0" xyz="0 0 -0.18"/>
   		<parent link="back_right_rotate"/>
   		<child link="back_right_wheel"/>
   		<axis xyz="0 0 1"/>  
 </joint>

<link name="camera_link">
        <visual>
    		<origin xyz="0 0 0" rpy="0 0 1.5707" />
             <geometry>
                <mesh filename="package://turtlebot_description/meshes/sensors/kinect.dae"/>
             </geometry>
        </visual>
  
      </link>

<joint name="base_link_to_camera_link" type="fixed">
   		<origin xyz="0.4 0 0.235" rpy="0 0 0"/>
   		<parent link="base_link"/>
   		<child link="camera_link"/>
</joint>



  <joint name="camera_depth_joint" type="fixed">
    <origin xyz="0 0 0" rpy="0 0 0" />
    <parent link="camera_link" />
    <child link="camera_depth_frame" />
  </joint>

  <link name="camera_depth_frame">
    <inertial>
      <mass value="0.01" />
      <inertia ixx="0.001" ixy="0.0" ixz="0.0"
        iyy="0.001" iyz="0.0"
        izz="0.001" />
    </inertial>
  </link>

  <joint name="camera_depth_optical_joint" type="fixed">
    <origin xyz="0 0 0" rpy="0 0 0" />
    <parent link="camera_depth_frame" />
    <child link="camera_depth_optical_frame" />
  </joint>

  <link name="camera_depth_optical_frame">
    <inertial>
      <mass value="0.001" />
      <inertia ixx="0.0001" ixy="0.0" ixz="0.0"
        iyy="0.0001" iyz="0.0"
        izz="0.0001" />
    </inertial>
  </link>

  <joint name="camera_rgb_joint" type="fixed">
    <origin xyz="0 0 0" rpy="0 0 0" />
    <parent link="camera_link" />
    <child link="camera_rgb_frame" />
  </joint>

  <link name="camera_rgb_frame">
    <inertial>
      <mass value="0.001" />
      <inertia ixx="0.0001" ixy="0.0" ixz="0.0"
        iyy="0.0001" iyz="0.0"
        izz="0.0001" />
    </inertial>
  </link>

  <joint name="camera_rgb_optical_joint" type="fixed">
    <origin xyz="0 0 0" rpy="0 0 0" />
    <parent link="camera_rgb_frame" />
    <child link="camera_rgb_optical_frame" />
  </joint>

  <link name="camera_rgb_optical_frame">
    <inertial>
      <mass value="0.001" />
      <inertia ixx="0.0001" ixy="0.0" ixz="0.0"
        iyy="0.0001" iyz="0.0"
        izz="0.0001" />
    </inertial>
  </link>




</robot>
